Workbook

Sheet data cadangan
A1: 56 | B1: #N/A | C1: DEPOSITO | D1: 6290003714 | E1: HARYANTO DJOJOE BUNTORO | F1: BANK UOB INDONESIA | G1: Indonesia | H1: IDR | I1: 2023 | J1: 0 | L1: 1 | N1: 522954440 | O1: 423213224 | P1: 0 | Q1: 0 | R1: 0
A2: 57 | B2: #N/A | C2: DEPOSITO | D2: 6290003714 | E2: HARYANTO DJOJOE BUNTORO | F2: BANK UOB INDONESIA | G2: Indonesia | H2: IDR | I2: 2023 | J2: 0 | L2: 1 | N2: 519743666 | O2: 575000000 | P2: 0 | Q2: 0 | R2: 0
A3: 58 | B3: #N/A | C3: DEPOSITO | D3: 6290003714 | E3: HARYANTO DJOJOE BUNTORO | F3: BANK UOB INDONESIA | G3: Indonesia | H3: IDR | I3: 2023 | J3: 0 | L3: 1 | N3: 514030503 | O3: 848290027 | P3: 0 | Q3: 0 | R3: 0
A4: 59 | B4: #N/A | C4: DEPOSITO | D4: 629000374 | E4: HARYANTO DJOJOE BUNTORO | F4: BANK UOB INDONESIA | G4: Indonesia | H4: IDR | I4: 2024 | J4: 0 | L4: 1 | N4: 514030503 | O4: 0 | P4: 0 | Q4: 0 | R4: 0
A5: 60 | B5: #N/A | C5: DEPOSITO | D5: 629000374 | E5: HARYANTO DJOJOE BUNTORO | F5: BANK UOB INDONESIA | G5: Indonesia | H5: IDR | I5: 2024 | J5: 0 | L5: 1 | N5: 505847387 | O5: 0 | P5: 0 | Q5: 0 | R5: 0
A6: 61 | B6: #N/A | C6: DEPOSITO | D6: 629000374 | E6: HARYANTO DJOJOE BUNTORO | F6: BANK UOB INDONESIA | G6: Indonesia | H6: IDR | I6: 2024 | J6: 0 | L6: 1 | N6: 1011694773 | O6: 0 | P6: 0 | Q6: 0 | R6: 0

Sheet 1770 (2)
B2: *) Pengisian kolom-kolom yang berisi nilai rupiah harus tanpa nilai desimal (contoh penulisan lihat petunjuk pengisian halaman 3)
AF3: RUPIAH *)
B5: A. PENGHASILAN NETO | G5: 1. | I5: PENGHASILAN NETO DALAM NEGERI DARI USAHA DAN/ATAU PEKERJAAN BEBAS [Diisi dari Formulir 1770 - I Halaman 1 Jumlah Bagian A atau Formulir 1770 - I Halaman 2 Jumlah Bagian B Kolom 5] | AF5: 1 | AG5: =BUPOT!F10 -> 52925263
G7: 2. | I7: PENGHASILAN NETO DALAM NEGERI SEHUBUNGAN DENGAN PEKERJAAN [Diisi dari Formulir 1770 - I Halaman 2 Jumlah Bagian C Kolom 5] | AF7: 2 | AG7: =BUPOT!F15 -> 111150000
G9: 3. | I9: PENGHASILAN NETO DALAM NEGERI LAINNYA [Diisi dari Formulir 1770 - I Halaman 2 Jumlah Bagian D Kolom 3] | AF9: 3 | AG9: 0
A10: 4
G11: 4. | I11: PENGHASILAN NETO LUAR NEGERI [Apabila memiliki penghasilan dari luar negeri agar diisi dari Lampiran Tersendiri, lihat petunjuk pengisian] | AF11: 4 | AG11: 0
G13: 5. | I13: JUMLAH PENGHASILAN NETO (1 + 2 + 3 + 4) | AF13: 5 | AG13: =AG5+AG7+AG9+AG11 -> 164075263
U14: …………………………………………………………………………………………………………………………..
G15: 6. | I15: ZAKAT / SUMBANGAN KEAGAMAAN YANG BERSIFAT WAJIB | AF15: 6 | AG15: 0
G17: 7. | I17: JUMLAH PENGHASILAN NETO SETELAH PENGURANGAN ZAKAT /SUMBANGAN KEAGAMAAN YANG | AF17: 7 | AG17: =AG13-AG15 -> 164075263
I18: SIFATNYA WAJIB ( 5- 6)
B21: B. PENGHASILAN KENA PAJAK | G21: 8. | I21: KOMPENSASI KERUGIAN | AF21: 8 | AG21: 0
G23: 9. | I23: JUMLAH PENGHASILAN NETO SETELAH KOMPENSASI KERUGIAN (7 - 8) | AF23: 9 | AG23: =AG17-AG21 -> 164075263
G25: 10. | I25: PENGHASILAN TIDAK KENA PAJAK | Q25: TK / | T25: K / | U25: 1 | W25: K / I / | AF25: 10 | AG25: 63000000
G27: 11. | I27: PENGHASILAN KENA PAJAK (9 -10) | AF27: 11 | AG27: =AG23-AG25 -> 101075263
B30: C. PPh TERUTANG | G30: 12. | I30: PPh TERUTANG (TARIF PASAL 17 UU PPh X ANGKA 11) [Bagi Wajib Pajak dengan status PH / MT diisi dari Lampiran Perhitungan PPh Terutang sebagaimana dimaksud dalam bagian G: Lampiran huruf i] | AF30: 12 | AG30: {=MAX(({5;15;25;30}%*(ROUNDDOWN($AG$27,-3))-{0;6000000;31000000;56000000}))} -> 9161250
G32: 13. | I32: PENGEMBALIAN/PENGURANGAN PPh PASAL 24 YANG TELAH DIKREDITKAN | AF32: 13 | AG32: 0
G35: 14. | I35: JUMLAH PPh TERUTANG ( 12 + 13) | AF35: 14 | AG35: =AG30+AG32 -> 9161250
B38: D. KREDIT PAJAK | G38: 15. | I38: PPh YANG DIPOTONG / DIPUNGUT OLEH PIHAK LAIN, PPh YANG DIBAYAR / DIPOTONG DI LUAR NEGERI DAN PPh DITANGGUNG PEMERINTAH [Diisi dari formulir 1770 -II Jumlah Bagian A Kolom 7] | AF38: 15 | AG38: =BUPOT!G16 -> 7687526
G40: 16. | I40: X | K40: a. | L40: PPh YANG HARUS DIBAYAR SENDIRI | U40: (14-15) | AF40: 16 | AG40: =AG35-AG38 -> 1473724
K42: b. | L42: PPh YANG LEBIH DIPOTONG/DIPUNGUT
G44: 17. | I44: PPh YANG DIBAYAR SENDIRI | P44: a. | Q44: PPh PASAL 25 BULANAN | AF44: 17a | AG44: 0
P46: b. | Q46: STP PPh PASAL 25 (HANYA POKOK PAJAK) | AF46: 17b
G49: 18. | I49: JUMLAH KREDIT PAJAK (17a+17b) | AF49: 18 | AG49: =AG44+AG46 -> 0
B51: E. PPh KURANG/ LEBIH BAYAR
G52: 19. | I52: a. | J52: X | K52: PPh YANG KURANG DIBAYAR (PPh PASAL 29) | U52: (16-18) | W52: TGL LUNAS | Y52: 3 | Z52: 1 | AA52: 0 | AB52: 3 | AC52: 2 | AD52: 6 | AF52: 19 | AG52: =AG40-AG49 -> 1473724
J53: \
I54: b. | K54: PPh YANG LEBIH DIBAYAR (PPh PASAL 28 A) | Y54: tgl | AA54: bln | AC54: thn
G56: 20. | I56: PERMOHONAN : PPh Lebih Bayar pada 19.b mohon | V56: a. | X56: DIRESTITUSIKAN | AC56: c. | AF56: DIKEMBALIKAN DENGAN SKPPKP PASAL 17C (WP dengan Kriteria Tertentu)
V59: b. | X59: DIPERHITUNGKAN DENGAN | AC59: d. | AF59: DIKEMBALIKAN DENGAN SKPPKP PASAL 17D (WP yang Memenuhi Persyaratan Tertentu)
X60: UTANG PAJAK
B62: F. ANGSURAN PPh PASAL 25 TAHUN PAJAK BERIKUTNYA
G63: 21. | I63: ANGSURAN PPh PASAL 25 TAHUN PAJAK BERIKUTNYA DIHITUNG SEBESAR | AF63: 21
I65: DIHITUNG BERDASARKAN :
I67: a. | K67: 1/12 X JUMLAH PADA ANGKA 16 | Z67: c. | AB67: PERHITUNGAN DALAM LAMPIRAN TERSENDIRI
I69: b. | K69: PERHITUNGAN WAJIB PAJAK ORANG PRIBADI PENGUSAHA TERTENTU

Sheet Sheet2
A3: Sum of SALDO SAAT INI (2025) | B3: Column Labels
B4: DEPOSITO | C4: DEPOSITO Total | D4: SETARA KAS LAINNYA | E4: SETARA KAS LAINNYA Total | F4: TABUNGAN | H4: TABUNGAN Total | I4: UANG TUNAI | J4: UANG TUNAI Total | K4: (blank) | L4: (blank) Total | M4: Grand Total
A5: Row Labels | B5: IDR | D5: IDR | F5: IDR | G5: USD | I5: IDR | K5: (blank)
A6: - | D6: 1050000000 | E6: 1050000000 | I6: 375000000 | J6: 375000000 | M6: 1425000000
A7: BANK CENTRAL ASIA | F7: 1849939508 | G7: 448197555 | H7: 2298137063 | M7: 2298137063
A8: BANK CIMB NIAGA | F8: 703053335 | H8: 703053335 | M8: 703053335
A9: BANK DBS INDONESIA | F9: 86378401 | G9: 10603064 | H9: 96981465 | M9: 96981465
A10: BANK HSBC INDONESIA | F10: 150158590 | G10: 76972876 | H10: 227131466 | M10: 227131466
A11: BANK MANDIRI | F11: 69884414 | H11: 69884414 | M11: 69884414
A12: BANK MAYBANK INDONESIA | F12: 289120215 | H12: 289120215 | M12: 289120215
A13: BANK MEGA | B13: 2076324773 | C13: 2076324773 | F13: 2365099919 | G13: 38368999 | H13: 2403468918 | M13: 4479793691
A14: BANK OCBC NISP | F14: 282662537 | H14: 282662537 | M14: 282662537
A15: BANK PAN INDONESIA | F15: 239621964 | G15: 280679210 | H15: 520301174 | M15: 520301174
A16: BANK UOB INDONESIA | F16: 700631451 | G16: 429021444 | H16: 1129652895 | M16: 1129652895
A17: STANDARD CHARTERED BANK | F17: 471794907 | G17: 7314772 | H17: 479109679 | M17: 479109679
A18: VALAS US DOLAR | I18: 590000000 | J18: 590000000 | M18: 590000000
A19: (blank)
A20: Grand Total | B20: 2076324773 | C20: 2076324773 | D20: 1050000000 | E20: 1050000000 | F20: 7208345241 | G20: 1291157920 | H20: 8499503161 | I20: 965000000 | J20: 965000000 | M20: 12590827934

Sheet KAS
C1: 1. KAS dan SETARA KAS | J1: AMBIL HANYA SAMPAI KOLOM J SAJA
C2: Uang Tunai/Tabungan/Giro/Deposito
C4: 3173042409640005 | D4: SINDJAJA JONANY | J4: =ROUNDDOWN(K4*L4,0) -> 0
B5: =VLOOKUP(C5,U:V,2,) -> #N/A | J5: =SUM(J8:J292) -> 11475827934 | L5: =VLOOKUP(H5,BUNGA!$C$97:$D$97,2,0) -> #N/A | N5: =SUM(N8:N292) -> 14579487152 | O5: =SUM(O8:O292) -> 2418393230 | P5: =SUM(P8:P292) -> 1972372290 | Q5: =SUM(Q8:Q292) -> 9193154695 | R5: =SUM(R8:R292) -> 13233927881
A6: NO | B6: KODE | C6: DESKRIPSI | D6: NOMOR AKUN | E6: ATAS NAMA | F6: NAMA BANK/INSTITUSI | G6: LOKASI HARTA | H6: KURS | I6: TAHUN PEROLEHAN | J6: SALDO SAAT INI (2025) | K6: SALDO DALAM BENTUK AWAL (2025) | L6: KURS | M6: (HARTA PPS/ HARTA INVESTASI PPS) | N6: NILAI TAHUN SEBELUMNYA
N7: 2024 | O7: 2023 | P7: 2022 | Q7: 2021 | R7: 2020 | T7: - | U7: - | V7: -
A8: 1 | B8: =VLOOKUP(C8,U:V,2,) -> 0102 | C8: TABUNGAN | D8: 30610081702 | E8: SINDJAJA JONANY | F8: STANDARD CHARTERED BANK | G8: Indonesia | H8: IDR | I8: 2025 | J8: =ROUNDDOWN(K8*L8,0) -> 395266344 | K8: 395266344 | L8: =VLOOKUP(H8,BUNGA!$C$97:$D$98,2,0) -> 1 | M8: SJ | N8: 121941664 | O8: 481437 | P8: 12040351 | Q8: 0 | R8: 0 | T8: 0101 | U8: UANG TUNAI | V8: 0101
A9: =A8+1 -> 2 | B9: =VLOOKUP(C9,U:V,2,) -> 0102 | C9: TABUNGAN | D9: 30607686992 | E9: SINDJAJA JONANY | F9: STANDARD CHARTERED BANK | G9: Indonesia | H9: IDR | I9: 2025 | J9: =ROUNDDOWN(K9*L9,0) -> 76528563 | K9: 76528563 | L9: =VLOOKUP(H9,BUNGA!$C$97:$D$98,2,0) -> 1 | M9: SJ | N9: 92634637 | O9: 974723 | P9: 12561571 | Q9: 0 | R9: 0 | T9: 0102 | U9: TABUNGAN | V9: 0102
A10: =A9+1 -> 3 | B10: =VLOOKUP(C10,U:V,2,) -> 0102 | C10: TABUNGAN | D10: 306812112560 | E10: ROSALINA CHANDRA | F10: STANDARD CHARTERED BANK | G10: Indonesia | H10: USD | I10: 2025 | J10: =ROUNDDOWN(K10*L10,0) -> 7314772 | K10: 436 | L10: =VLOOKUP(H10,BUNGA!$C$97:$D$98,2,0) -> 16777 | M10: RC | N10: 56429070 | O10: 5004180 | P10: 0 | Q10: 0 | R10: 0 | T10: 0103 | U10: GIRO | V10: 0103
A11: =A10+1 -> 4 | B11: =VLOOKUP(C11,U:V,2,) -> 0102 | C11: TABUNGAN | D11: 010210020072665 | E11: SINDJAJA JONANY | F11: BANK MEGA | G11: Indonesia | H11: IDR | I11: 2025 | J11: =ROUNDDOWN(K11*L11,0) -> 129148067 | K11: 129148067 | L11: =VLOOKUP(H11,BUNGA!$C$97:$D$98,2,0) -> 1 | M11: SJ | N11: 84858925 | O11: 22058140 | P11: 71975639 | Q11: 181789681 | R11: 188528896 | T11: 0104 | U11: DEPOSITO | V11: 0104
A12: =A11+1 -> 5 | B12: =VLOOKUP(C12,U:V,2,) -> 0102 | C12: TABUNGAN | D12: 010210020079229 | E12: ROSALINA CHANDRA | F12: BANK MEGA | G12: Indonesia | H12: IDR | I12: 2025 | J12: =ROUNDDOWN(K12*L12,0) -> 121185719 | K12: 121185719 | L12: =VLOOKUP(H12,BUNGA!$C$97:$D$98,2,0) -> 1 | M12: RC | N12: 3776657 | O12: 134948 | P12: 21856286 | Q12: 28421979 | R12: 0 | T12: 0105 | U12: UANG ELEKTRONIK | V12: 0105
A13: =A12+1 -> 6 | B13: =VLOOKUP(C13,U:V,2,) -> 0102 | C13: TABUNGAN | D13: 010212029003270 | E13: SINDJAJA JONANY | F13: BANK MEGA | G13: Indonesia | H13: USD | I13: 2025 | J13: =ROUNDDOWN(K13*L13,0) -> 38368999 | K13: 2287 | L13: =VLOOKUP(H13,BUNGA!$C$97:$D$98,2,0) -> 16777 | M13: SJ | N13: 27281025 | O13: 26179275 | P13: 52731000 | Q13: 62064548 | R13: 120454248 | T13: 0106 | U13: CEK | V13: 0106
A14: =A13+1 -> 7 | B14: =VLOOKUP(C14,U:V,2,) -> 0102 | C14: TABUNGAN | D14: 010210036010740 | E14: SINDJAJA JONANY | F14: BANK MEGA | G14: Indonesia | H14: IDR | I14: 2025 | J14: =ROUNDDOWN(K14*L14,0) -> 2114766133 | K14: 2114766133 | L14: =VLOOKUP(H14,BUNGA!$C$97:$D$98,2,0) -> 1 | M14: SJ | N14: 0 | O14: 0 | P14: 0 | Q14: 0 | R14: 0 | T14: 0107 | U14: WESSEL | V14: 0107
A15: =A14+1 -> 8 | B15: =VLOOKUP(C15,U:V,2,) -> 0104 | C15: DEPOSITO | D15: 0102100200360006730 | E15: ROSALINA CHANDRA | F15: BANK MEGA | G15: Indonesia | H15: IDR | I15: 2025 | J15: =ROUNDDOWN(K15*L15,0) -> 1576324773 | K15: 1576324773 | L15: =VLOOKUP(H15,BUNGA!$C$97:$D$98,2,0) -> 1 | M15: RC | N15: 0 | O15: 0 | P15: 0 | Q15: 0 | R15: 0 | T15: 0108 | U15: KERTAS KOMERSIAL | V15: 0108
A16: =A15+1 -> 9 | B16: =VLOOKUP(C16,U:V,2,) -> 0104 | C16: DEPOSITO | D16: 010210036007967 | E16: ROSALINA CHANDRA | F16: BANK MEGA | G16: Indonesia | H16: IDR | I16: 2025 | J16: =ROUNDDOWN(K16*L16,0) -> 500000000 | K16: 500000000 | L16: =VLOOKUP(H16,BUNGA!$C$97:$D$98,2,0) -> 1 | M16: RC | N16: 0 | O16: 0 | P16: 0 | Q16: 0 | R16: 0 | T16: 0109 | U16: SETARA KAS | V16: 0109
A17: =A16+1 -> 10 | B17: =VLOOKUP(C17,U:V,2,) -> 0102 | C17: TABUNGAN | D17: 5910502699 | E17: SINDJAJA JONANY | F17: BANK CENTRAL ASIA | G17: Indonesia | H17: IDR | I17: 2025 | J17: =ROUNDDOWN(K17*L17,0) -> 623690638 | K17: 623690638 | L17: =VLOOKUP(H17,BUNGA!$C$97:$D$98,2,0) -> 1 | M17: SJ | N17: 395980369 | O17: 58844070 | P17: 84236265 | Q17: 73625229 | R17: 42296991 | T17: 0101 | U17: UANG TUNAI/BANK NOTE/KOIN | V17: 0101
A18: =A17+1 -> 11 | B18: =VLOOKUP(C18,U:V,2,) -> 0102 | C18: TABUNGAN | D18: 8740285689 | E18: SINDJAJA JONANY | F18: BANK CENTRAL ASIA | G18: Indonesia | H18: IDR | I18: 2025 | J18: =ROUNDDOWN(K18*L18,0) -> 298564906 | K18: 298564906 | L18: =VLOOKUP(H18,BUNGA!$C$97:$D$98,2,0) -> 1 | M18: SJ | N18: 431828577 | O18: 117767462 | P18: 127485150 | Q18: 24878970 | R18: 354451437 | T18: 0109 | U18: SETARA KAS LAINNYA | V18: 0109
A19: =A18+1 -> 12 | B19: =VLOOKUP(C19,U:V,2,) -> 0102 | C19: TABUNGAN | D19: 8740530683 | E19: SINDJAJA JONANY | F19: BANK CENTRAL ASIA | G19: Indonesia | H19: USD | I19: 2025 | J19: =ROUNDDOWN(K19*L19,0) -> 279018287 | K19: 16631 | L19: =VLOOKUP(H19,BUNGA!$C$97:$D$98,2,0) -> 16777 | M19: SJ | N19: 11604495 | O19: 0 | P19: 0 | Q19: 0 | R19: 0
A20: =A19+1 -> 13 | B20: =VLOOKUP(C20,U:V,2,) -> 0102 | C20: TABUNGAN | D20: 8740185668 | E20: ROSALINA CHANDRA | F20: BANK CENTRAL ASIA | G20: Indonesia | H20: IDR | I20: 2025 | J20: =ROUNDDOWN(K20*L20,0) -> 158216505 | K20: 158216505 | L20: =VLOOKUP(H20,BUNGA!$C$97:$D$98,2,0) -> 1 | M20: RC | N20: 508484117 | O20: 267041301 | P20: 36497755 | Q20: 173685791 | R20: 233518380
A21: =A20+1 -> 14 | B21: =VLOOKUP(C21,U:V,2,) -> 0102 | C21: TABUNGAN | D21: 8740351711 | E21: ROSALINA CHANDRA | F21: BANK CENTRAL ASIA | G21: Indonesia | H21: IDR | I21: 2025 | J21: =ROUNDDOWN(K21*L21,0) -> 769467459 | K21: 769467459 | L21: =VLOOKUP(H21,BUNGA!$C$97:$D$98,2,0) -> 1 | M21: RC | N21: 956098574 | O21: 48237792 | P21: 91749141 | Q21: 0 | R21: 0
A22: =A21+1 -> 15 | B22: =VLOOKUP(C22,U:V,2,) -> 0102 | C22: TABUNGAN | D22: 5910700598 | E22: ROSALINA CHANDRA | F22: BANK CENTRAL ASIA | G22: Indonesia | H22: USD | I22: 2025 | J22: =ROUNDDOWN(K22*L22,0) -> 169179268 | K22: 10084 | L22: =VLOOKUP(H22,BUNGA!$C$97:$D$98,2,0) -> 16777 | M22: RC | N22: 312452235 | O22: 125397955 | P22: 45539000 | Q22: 51687104 | R22: 100563504
A23: =A22+1 -> 16 | B23: =VLOOKUP(C23,U:V,2,) -> 0102 | C23: TABUNGAN | D23: 0702102299 | E23: SINDJAJA JONANY | F23: BANK PAN INDONESIA | G23: Indonesia | H23: IDR | I23: 2025 | J23: =ROUNDDOWN(K23*L23,0) -> 117449710 | K23: 117449710 | L23: =VLOOKUP(H23,BUNGA!$C$97:$D$98,2,0) -> 1 | M23: SJ | N23: 34224869 | O23: 7418816 | P23: 16621048 | Q23: 3082257 | R23: 0
A24: =A23+1 -> 17 | B24: =VLOOKUP(C24,U:V,2,) -> 0102 | C24: TABUNGAN | D24: 0704400221 | E24: SINDJAJA JONANY | F24: BANK PAN INDONESIA | G24: Indonesia | H24: USD | I24: 2025 | J24: =ROUNDDOWN(K24*L24,0) -> 280679210 | K24: 16730 | L24: =VLOOKUP(H24,BUNGA!$C$97:$D$98,2,0) -> 16777 | M24: SJ | N24: 100143090 | O24: 25623255 | P24: 26799500 | Q24: 503163094 | R24: 432460060
A25: =A24+1 -> 18 | B25: =VLOOKUP(C25,U:V,2,) -> 0102 | C25: TABUNGAN | D25: 0702013221 | E25: ROSALINA CHANDRA | F25: BANK PAN INDONESIA | G25: Indonesia | H25: IDR | I25: 2025 | J25: =ROUNDDOWN(K25*L25,0) -> 122172254 | K25: 122172254 | L25: =VLOOKUP(H25,BUNGA!$C$97:$D$98,2,0) -> 1 | M25: RC | N25: 45154004 | O25: 9618501 | P25: 18320983 | Q25: 6245711 | R25: 0
A26: =A25+1 -> 19 | B26: =VLOOKUP(C26,U:V,2,) -> 0102 | C26: TABUNGAN | D26: 702531238600 | E26: SINDJAJA JONANY | F26: BANK CIMB NIAGA | G26: Indonesia | H26: IDR | I26: 2025 | J26: =ROUNDDOWN(K26*L26,0) -> 629283803 | K26: 629283803 | L26: =VLOOKUP(H26,BUNGA!$C$97:$D$98,2,0) -> 1 | M26: SJ | N26: 174126066 | O26: 5647422 | P26: 5635819 | Q26: 1842731 | R26: 0
A27: =A26+1 -> 20 | B27: =VLOOKUP(C27,U:V,2,) -> 0102 | C27: TABUNGAN | D27: 700884870600 | E27: SINDJAJA JONANY | F27: BANK CIMB NIAGA | G27: Indonesia | H27: IDR | I27: 2025 | J27: =ROUNDDOWN(K27*L27,0) -> 53819698 | K27: 53819698 | L27: =VLOOKUP(H27,BUNGA!$C$97:$D$98,2,0) -> 1 | M27: SJ | N27: 149441785 | O27: 0 | P27: 0 | Q27: 0 | R27: 0
A28: =A27+1 -> 21 | B28: =VLOOKUP(C28,U:V,2,) -> 0102 | C28: TABUNGAN | D28: 701031763000 | E28: ROSALINA CHANDRA | F28: BANK CIMB NIAGA | G28: Indonesia | H28: IDR | I28: 2025 | J28: =ROUNDDOWN(K28*L28,0) -> 19949834 | K28: 19949834 | L28: =VLOOKUP(H28,BUNGA!$C$97:$D$98,2,0) -> 1 | M28: RC | N28: 4999856 | O28: 8874867 | P28: 97603432 | Q28: 14822490 | R28: 0
A29: =A28+1 -> 22 | B29: =VLOOKUP(C29,U:V,2,) -> 0102 | C29: TABUNGAN | D29: 27810193121 | E29: ROSALINA CHANDRA | F29: BANK OCBC NISP | G29: Indonesia | H29: IDR | I29: 2025 | J29: =ROUNDDOWN(K29*L29,0) -> 282662537 | K29: 282662537 | L29: =VLOOKUP(H29,BUNGA!$C$97:$D$98,2,0) -> 1 | M29: RC | N29: 225113597 | O29: 0 | P29: 0 | Q29: 0 | R29: 0
A30: =A29+1 -> 23 | B30: =VLOOKUP(C30,U:V,2,) -> 0102 | C30: TABUNGAN | D30: 1680011168885 | E30: ROSALINA CHANDRA | F30: BANK MANDIRI | G30: Indonesia | H30: IDR | I30: 2025 | J30: =ROUNDDOWN(K30*L30,0) -> 69884414 | K30: 69884414 | L30: =VLOOKUP(H30,BUNGA!$C$97:$D$98,2,0) -> 1 | M30: RC | N30: 131871464 | O30: 45421741 | P30: 88218785 | Q30: 103010634 | R30: 162755079
... A44: =A43+1 -> 37 | B44: =VLOOKUP(C44,U:V,2,) -> 0102 | C44: TABUNGAN | D44: 6419000709 | E44: SINDJAJA JONANY | F44: BANK UOB INDONESIA | G44: Indonesia | H44: USD | I44: 2025 | J44: =ROUNDDOWN(K44*L44,0) -> 15401286 | K44: 918 | L44: =VLOOKUP(H44,BUNGA!$C$97:$D$98,2,0) -> 16777 | M44: SJ | N44: 53660730 | O44: 0 | P44: 0 | Q44: 0 | R44: 0
A45: =A44+1 -> 38 | B45: =VLOOKUP(C45,U:V,2,) -> 0102 | C45: TABUNGAN | D45: 6309003261 | E45: SINDJAJA JONANY | F45: BANK UOB INDONESIA | G45: Indonesia | H45: IDR | I45: 2025 | J45: =ROUNDDOWN(K45*L45,0) -> 563263882 | K45: 563263882 | L45: =VLOOKUP(H45,BUNGA!$C$97:$D$98,2,0) -> 1 | M45: SJ | N45: 0 | O45: 0 | P45: 0 | Q45: 0 | R45: 0
A46: =A45+1 -> 39 | B46: =VLOOKUP(C46,U:V,2,) -> 0102 | C46: TABUNGAN | D46: 6419000059 | E46: SINDJAJA JONANY | F46: BANK UOB INDONESIA | G46: Indonesia | H46: USD | I46: 2025 | J46: =ROUNDDOWN(K46*L46,0) -> 73382598 | K46: 4374 | L46: =VLOOKUP(H46,BUNGA!$C$97:$D$98,2,0) -> 16777 | M46: SJ | N46: 0 | O46: 0 | P46: 0 | Q46: 0 | R46: 0
A47: =A46+1 -> 40 | B47: =VLOOKUP(C47,U:V,2,) -> 0102 | C47: TABUNGAN | D47: 6309003831 | E47: ROSALINA CHANDRA | F47: BANK UOB INDONESIA | G47: Indonesia | H47: IDR | I47: 2025 | J47: =ROUNDDOWN(K47*L47,0) -> 88959334 | K47: 88959334 | L47: =VLOOKUP(H47,BUNGA!$C$97:$D$98,2,0) -> 1 | M47: RC | N47: 0 | O47: 0 | P47: 0 | Q47: 0 | R47: 0
A48: =A47+1 -> 41 | B48: =VLOOKUP(C48,U:V,2,) -> 0102 | C48: TABUNGAN | D48: 6309001742 | E48: ROSALINA CHANDRA | F48: BANK UOB INDONESIA | G48: Indonesia | H48: USD | I48: 2025 | J48: =ROUNDDOWN(K48*L48,0) -> 83029373 | K48: 4949 | L48: =VLOOKUP(H48,BUNGA!$C$97:$D$98,2,0) -> 16777 | M48: RC | N48: 0 | O48: 0 | P48: 0 | Q48: 0 | R48: 0
A49: =A48+1 -> 42 | B49: =VLOOKUP(C49,U:V,2,) -> 0109 | C49: SETARA KAS LAINNYA | D49: - | E49: SINDJAJA JONANY | F49: - | G49: Indonesia | H49: IDR | I49: 2025 | J49: =ROUNDDOWN(K49*L49,0) -> 600000000 | K49: 600000000 | L49: =VLOOKUP(H49,BUNGA!$C$97:$D$98,2,0) -> 1 | M49: SJ | N49: 1050000000 | O49: 500000000 | P49: 0 | Q49: 0 | R49: 0
A50: =A49+1 -> 43 | B50: =VLOOKUP(C50,U:V,2,) -> 0101 | C50: UANG TUNAI | D50: - | E50: SINDJAJA JONANY | F50: VALAS US DOLAR (sebagian diinvestasikan) | G50: Indonesia | H50: IDR | I50: 2021 | J50: =ROUNDDOWN(K50*L50,0) -> 50000000 | K50: 50000000 | L50: =VLOOKUP(H50,BUNGA!$C$97:$D$98,2,0) -> 1 | M50: SJ | N50: 590000000 | O50: 590000000 | P50: 590000000 | Q50: 590000000 | R50: 590000000
A51: =A50+1 -> 44 | B51: =VLOOKUP(C51,U:V,2,) -> 0101 | C51: UANG TUNAI | D51: - | E51: SINDJAJA JONANY | F51: - | G51: Indonesia | H51: IDR | I51: 2025 | J51: =ROUNDDOWN(K51*L51,0) -> 250000000 | K51: 250000000 | L51: =VLOOKUP(H51,BUNGA!$C$97:$D$98,2,0) -> 1 | M51: SJ | N51: 375000000 | O51: 152575000 | P51: 102575000 | Q51: 325750000 | R51: 100000000
B71: =VLOOKUP(C71,U:V,2,) -> 0104 | C71: DEPOSITO | D71: Deposito 30152041 | F71: BANK MEGA | G71: Indonesia | H71: IDR | I71: 2020 | J71: CLOSE | K71: CLOSE | L71: CLOSE | M71: - | N71: 0 | O71: 0 | P71: 0 | Q71: 670000000 | R71: 670000000
B72: =VLOOKUP(C72,U:V,2,) -> 0104 | C72: DEPOSITO | D72: Deposito 6788 | F72: BANK MEGA | G72: Indonesia | H72: IDR | I72: 2024 | J72: CLOSE | K72: CLOSE | L72: CLOSE | M72: - | N72: 2000000000 | O72: 0 | P72: 0 | Q72: 0 | R72: 0
B73: =VLOOKUP(C73,U:V,2,) -> 0104 | C73: DEPOSITO | D73: Deposito 7374 | F73: BANK MEGA | G73: Indonesia | H73: IDR | I73: 2024 | J73: CLOSE | K73: CLOSE | L73: CLOSE | M73: - | N73: 2000000000 | O73: 0 | P73: 0 | Q73: 0 | R73: 0
...

Sheet INVEST
C1: 3. INVESTASI/SEKURITAS
C2: Saham yang dibeli untuk dijual kembali/Saham Non Bursa/Saham Bursa/Obligasi Perusahaan/Obligasi Pemerintah IndonesiaSurat Utang Lainnya/Asuransi/Unit Link di Asuransi
C4: 3173042409640005 | D4: SINDJAJA JONANY
J5: =SUM(J8:J215) -> 229892184504 | L5: =SUM(L8:L215) -> 230091984504 | P5: =SUM(P8:P215) -> 157557581602 | Q5: =SUM(Q8:Q215) -> 133490009839 | R5: =SUM(R8:R215) -> 124003495797 | S5: =SUM(S8:S215) -> 127567111319 | T5: =SUM(T8:T215) -> 133023244249
A6: NO | B6: KODE | C6: DESKRIPSI | D6: LOKASI HARTA | E6: BANK / INSTITUSI / PENERIMA INVESTASI | G6: NOMOR AKUN | H6: KODE BANK | I6: KURS | J6: HARGA PEROLEHAN | K6: TAHUN PEROLEHAN | L6: NILAI SAAT INI (2025) | M6: SALDO DALAM BENTUK AWAL (2025) | N6: KURS | O6: (HARTA PPS/ HARTA INVESTASI PPS) | P6: NILAI TAHUN SEBELUMNYA
E7: NPWP | F7: NAMA | P7: 2024 | Q7: 2023 | R7: 2022 | S7: 2021 | T7: 2020 | V7: - | W7: - | X7: -
A8: 1 | B8: =VLOOKUP(C8,$W:$X,2,0) -> 0305 | C8: OBLIGASI PEMERINTAH | D8: Indonesia | E8: 0010003358091000 | F8: STANDARD CHARTERED BANK | G8: OBLIGASI FR 75 | H8: SC | I8: IDR | J8: 1095750000 | K8: 2025 | L8: =ROUNDDOWN(M8*N8,0) -> 1095750000 | M8: 1095750000 | N8: =VLOOKUP(I8,BUNGA!$C$97:$D$98,2,0) -> 1 | O8: SJ | P8: 1000000000 | Q8: 1000000000 | R8: 1000000000 | S8: 1000000000 | T8: 1000000000 | V8: 0301 | W8: SAHAM YANG DIBELI UNTUK DIJUAL KEMBALI | X8: 0301
A9: =A8+1 -> 2 | B9: =VLOOKUP(C9,$W:$X,2,0) -> 0305 | C9: OBLIGASI PEMERINTAH | D9: Indonesia | E9: 0010003358091000 | F9: STANDARD CHARTERED BANK | G9: OBLIGASI FR 80 | H9: SC | I9: IDR | J9: 437628000 | K9: 2025 | L9: =ROUNDDOWN(M9*N9,0) -> 437628000 | M9: 437628000 | N9: =VLOOKUP(I9,BUNGA!$C$97:$D$98,2,0) -> 1 | O9: SJ | P9: 400000000 | Q9: 400000000 | R9: 400000000 | S9: 400000000 | T9: 400000000 | V9: 0302 | W9: SAHAM NON BURSA | X9: 0302
A10: =A9+1 -> 3 | B10: =VLOOKUP(C10,$W:$X,2,0) -> 0305 | C10: OBLIGASI PEMERINTAH | D10: Indonesia | E10: 0010003358091000 | F10: STANDARD CHARTERED BANK | G10: FR064 | H10: SC | I10: IDR | J10: 1850000000 | K10: 2025 | L10: =ROUNDDOWN(M10*N10,0) -> 1850000000 | M10: 1850000000 | N10: =VLOOKUP(I10,BUNGA!$C$97:$D$98,2,0) -> 1 | O10: - | P10: 1850000000 | Q10: 1850000000 | R10: 0 | S10: 0 | T10: 0 | V10: 0303 | W10: SAHAM BURSA | X10: 0303
A11: =A10+1 -> 4 | B11: =VLOOKUP(C11,$W:$X,2,0) -> 0305 | C11: OBLIGASI PEMERINTAH | D11: Indonesia | E11: 0010003358091000 | F11: STANDARD CHARTERED BANK | G11: ST011 | H11: SC | I11: IDR | J11: 2370000000 | K11: 2025 | L11: =ROUNDDOWN(M11*N11,0) -> 2370000000 | M11: 2370000000 | N11: =VLOOKUP(I11,BUNGA!$C$97:$D$98,2,0) -> 1 | O11: RC | P11: 2370000000 | Q11: 2370000000 | R11: 0 | S11: 0 | T11: 0 | V11: 0304 | W11: OBLIGASI PERUSAHAAN | X11: 0304
A12: =A11+1 -> 5 | B12: =VLOOKUP(C12,$W:$X,2,0) -> 0399 | C12: INVESTASI LAINNYA | D12: Indonesia | E12: 0010003358091000 | F12: STANDARD CHARTERED BANK | G12: ASURANSI PRUDENTIAL UMP | H12: SC | I12: IDR | J12: 901170423 | K12: 2025 | L12: =ROUNDDOWN(M12*N12,0) -> 901170423 | M12: 901170423 | N12: =VLOOKUP(I12,BUNGA!$C$97:$D$98,2,0) -> 1 | O12: SJ | P12: 109394265 | Q12: 0 | R12: 0 | S12: 0 | T12: 0 | V12: 0305 | W12: OBLIGASI PEMERINTAH | X12: 0305
A13: =A12+1 -> 6 | B13: =VLOOKUP(C13,$W:$X,2,0) -> 0399 | C13: INVESTASI LAINNYA | D13: Indonesia | E13: 0010003358091000 | F13: STANDARD CHARTERED BANK | G13: ASURANSI PRUDENTIAL VIA | H13: SC | I13: IDR | J13: 1280003810 | K13: 2025 | L13: =ROUNDDOWN(M13*N13,0) -> 1280003810 | M13: 1280003810 | N13: =VLOOKUP(I13,BUNGA!$C$97:$D$98,2,0) -> 1 | O13: SJ | P13: 197646600 | Q13: 0 | R13: 0 | S13: 0 | T13: 0 | V13: 0306 | W13: SURAT UTANG LAINNYA | X13: 0306
A14: =A13+1 -> 7 | B14: =VLOOKUP(C14,$W:$X,2,0) -> 0307 | C14: REKSADANA | D14: Indonesia | E14: 0013781138024000 | F14: Manulife Obligasi Negara Indonesia II | G14: - | H14: SC | I14: IDR | J14: =M14 -> 1406054056 | K14: 2025 | L14: =ROUNDDOWN(M14*N14,0) -> 1406054056 | M14: 1406054056 | N14: =VLOOKUP(I14,BUNGA!$C$97:$D$98,2,0) -> 1 | O14: SJ | P14: 0 | Q14: 0 | R14: 0 | S14: 0 | T14: 0 | V14: 0307 | W14: REKSADANA | X14: 0307
A15: =A14+1 -> 8 | B15: =VLOOKUP(C15,$W:$X,2,0) -> 0307 | C15: REKSADANA | D15: Indonesia | E15: 0013781138024000 | F15: Manulife Obligasi Negara Indonesia II | G15: - | H15: SC | I15: IDR | J15: =M15 -> 398528728 | K15: 2025 | L15: =ROUNDDOWN(M15*N15,0) -> 398528728 | M15: 398528728 | N15: =VLOOKUP(I15,BUNGA!$C$97:$D$98,2,0) -> 1 | O15: SJ | P15: 0 | Q15: 0 | R15: 0 | S15: 0 | T15: 0 | V15: 0309 | W15: PENYERTAAN MODAL DALAM PERUSAHAAN LAIN YANG BUKAN ATAS SAHAM | X15: 0309
A16: =A15+1 -> 9 | B16: =VLOOKUP(C16,$W:$X,2,0) -> 0307 | C16: REKSADANA | D16: Indonesia | E16: 0033154576063000 | F16: Manulife USD Fixed Income Kelas A2 | G16: - | H16: SC | I16: USD | J16: =L16 -> 374093546 | K16: 2025 | L16: =ROUNDDOWN(M16*N16,0) -> 374093546 | M16: 22298 | N16: =VLOOKUP(I16,BUNGA!$C$97:$D$98,2,0) -> 16777 | O16: SJ | P16: 0 | Q16: 0 | R16: 0 | S16: 0 | T16: 0 | V16: 0310 | W16: ASURANSI | X16: 0310
A17: =A16+1 -> 10 | B17: =VLOOKUP(C17,$W:$X,2,0) -> 0307 | C17: REKSADANA | D17: Indonesia | E17: 0013781138024000 | F17: Manulife Obligasi Negara Indonesia II | G17: - | H17: SC | I17: IDR | J17: =M17 -> 1287534772 | K17: 2025 | L17: =ROUNDDOWN(M17*N17,0) -> 1287534772 | M17: 1287534772 | N17: =VLOOKUP(I17,BUNGA!$C$97:$D$98,2,0) -> 1 | O17: RC | P17: 0 | Q17: 0 | R17: 0 | S17: 0 | T17: 0 | V17: 0311 | W17: UNIT LINK DI ASURANSI | X17: 0311
A18: =A17+1 -> 11 | B18: =VLOOKUP(C18,$W:$X,2,0) -> 0305 | C18: OBLIGASI PEMERINTAH | D18: Indonesia | E18: 0010003358091000 | F18: STANDARD CHARTERED BANK | G18: USD INDON 34 | H18: SC | I18: USD | J18: =L18 -> 2013240000 | K18: 2025 | L18: =ROUNDDOWN(M18*N18,0) -> 2013240000 | M18: 120000 | N18: =VLOOKUP(I18,BUNGA!$C$97:$D$98,2,0) -> 16777 | O18: SJ | P18: 0 | Q18: 0 | R18: 0 | S18: 0 | T18: 0 | V18: 0399 | W18: INVESTASI LAINNYA | X18: 0399
A19: =A18+1 -> 12 | B19: =VLOOKUP(C19,$W:$X,2,0) -> 0305 | C19: OBLIGASI PEMERINTAH | D19: Indonesia | E19: 0010003358091000 | F19: STANDARD CHARTERED BANK | G19: SR 021 | H19: SC | I19: IDR | J19: 1984096000 | K19: 2025 | L19: =ROUNDDOWN(M19*N19,0) -> 1984096000 | M19: 1984096000 | N19: =VLOOKUP(I19,BUNGA!$C$97:$D$98,2,0) -> 1 | O19: SJ | P19: 0 | Q19: 0 | R19: 0 | S19: 0 | T19: 0
A20: =A19+1 -> 13 | B20: =VLOOKUP(C20,$W:$X,2,0) -> 0305 | C20: OBLIGASI PEMERINTAH | D20: Indonesia | E20: 0010003358091000 | F20: STANDARD CHARTERED BANK | G20: SR022 T5 | H20: SC | I20: IDR | J20: 2000000000 | K20: 2025 | L20: =ROUNDDOWN(M20*N20,0) -> 2000000000 | M20: 2000000000 | N20: =VLOOKUP(I20,BUNGA!$C$97:$D$98,2,0) -> 1 | O20: SJ | P20: 0 | Q20: 0 | R20: 0 | S20: 0 | T20: 0
A21: =A20+1 -> 14 | B21: =VLOOKUP(C21,$W:$X,2,0) -> 0305 | C21: OBLIGASI PEMERINTAH | D21: Indonesia | E21: 0010003358091000 | F21: STANDARD CHARTERED BANK | G21: ST014 T4 | H21: SC | I21: IDR | J21: 1700000000 | K21: 2025 | L21: =ROUNDDOWN(M21*N21,0) -> 1700000000 | M21: 1700000000 | N21: =VLOOKUP(I21,BUNGA!$C$97:$D$98,2,0) -> 1 | O21: SJ | P21: 0 | Q21: 0 | R21: 0 | S21: 0 | T21: 0
A22: =A21+1 -> 15 | B22: =VLOOKUP(C22,$W:$X,2,0) -> 0305 | C22: OBLIGASI PEMERINTAH | D22: Indonesia | E22: 0010003358091000 | F22: STANDARD CHARTERED BANK | G22: FR 58 | H22: SC | I22: IDR | J22: 2500000000 | K22: 2025 | L22: =ROUNDDOWN(M22*N22,0) -> 2500000000 | M22: 2500000000 | N22: =VLOOKUP(I22,BUNGA!$C$97:$D$98,2,0) -> 1 | O22: SJ | P22: 0 | Q22: 0 | R22: 0 | S22: 0 | T22: 0 | V22: OWNERSHIP MOVEABLE ASSET
A23: =A22+1 -> 16 | B23: =VLOOKUP(C23,$W:$X,2,0) -> 0305 | C23: OBLIGASI PEMERINTAH | D23: Indonesia | E23: 0010003358091000 | F23: STANDARD CHARTERED BANK | G23: ORI27 T6 | H23: SC | I23: IDR | J23: 2180000000 | K23: 2025 | L23: =ROUNDDOWN(M23*N23,0) -> 2180000000 | M23: 2180000000 | N23: =VLOOKUP(I23,BUNGA!$C$97:$D$98,2,0) -> 1 | O23: SJ | P23: 0 | Q23: 0 | R23: 0 | S23: 0 | T23: 0 | V23: Code | W23: Code Description
A24: =A23+1 -> 17 | B24: =VLOOKUP(C24,$W:$X,2,0) -> 0305 | C24: OBLIGASI PEMERINTAH | D24: Indonesia | E24: 0010003358091000 | F24: STANDARD CHARTERED BANK | G24: FR 78 | H24: SC | I24: IDR | J24: 1220000000 | K24: 2025 | L24: =ROUNDDOWN(M24*N24,0) -> 1220000000 | M24: 1220000000 | N24: =VLOOKUP(I24,BUNGA!$C$97:$D$98,2,0) -> 1 | O24: SJ | P24: 0 | Q24: 0 | R24: 0 | S24: 0 | T24: 0 | V24: OTHER | W24: Atas nama pihak lain
A25: =A24+1 -> 18 | B25: =VLOOKUP(C25,$W:$X,2,0) -> 0305 | C25: OBLIGASI PEMERINTAH | D25: Indonesia | E25: 0010003358091000 | F25: STANDARD CHARTERED BANK | G25: ST015 T2 | H25: SC | I25: IDR | J25: 3000000000 | K25: 2025 | L25: =ROUNDDOWN(M25*N25,0) -> 3000000000 | M25: 3000000000 | N25: =VLOOKUP(I25,BUNGA!$C$97:$D$98,2,0) -> 1 | O25: SJ | P25: 0 | Q25: 0 | R25: 0 | S25: 0 | T25: 0 | V25: TAXPAYER | W25: Atas nama sendiri
A26: =A25+1 -> 19 | B26: =VLOOKUP(C26,$W:$X,2,0) -> 0305 | C26: OBLIGASI PEMERINTAH | D26: Indonesia | E26: 0010003358091000 | F26: STANDARD CHARTERED BANK | G26: SBR014 T2 | H26: SC | I26: IDR | J26: 620000000 | K26: 2025 | L26: =ROUNDDOWN(M26*N26,0) -> 620000000 | M26: 620000000 | N26: =VLOOKUP(I26,BUNGA!$C$97:$D$98,2,0) -> 1 | O26: RC | P26: 0 | Q26: 0 | R26: 0 | S26: 0 | T26: 0
A27: =A26+1 -> 20 | B27: =VLOOKUP(C27,$W:$X,2,0) -> 0305 | C27: OBLIGASI PEMERINTAH | D27: Indonesia | E27: 0010003358091000 | F27: STANDARD CHARTERED BANK | G27: SR021 T5 | H27: SC | I27: IDR | J27: 2150000000 | K27: 2025 | L27: =ROUNDDOWN(M27*N27,0) -> 2150000000 | M27: 2150000000 | N27: =VLOOKUP(I27,BUNGA!$C$97:$D$98,2,0) -> 1 | O27: RC | P27: 0 | Q27: 0 | R27: 0 | S27: 0 | T27: 0
A28: =A27+1 -> 21 | B28: =VLOOKUP(C28,$W:$X,2,0) -> 0305 | C28: OBLIGASI PEMERINTAH | D28: Indonesia | E28: 0011080454091000 | F28: BANK MEGA | G28: USD INDOIS 27 | H28: MG | I28: USD | J28: 3355400000 | K28: 2025 | L28: =ROUNDDOWN(M28*N28,0) -> 3355400000 | M28: 200000 | N28: =VLOOKUP(I28,BUNGA!$C$97:$D$98,2,0) -> 16777 | O28: SJ | P28: 0 | Q28: 0 | R28: 0 | S28: 0 | T28: 0
A29: =A28+1 -> 22 | B29: =VLOOKUP(C29,$W:$X,2,0) -> 0305 | C29: OBLIGASI PEMERINTAH | D29: Indonesia | E29: 0013084496091000 | F29: BANK CENTRAL ASIA | G29: OBLIGASI FR68 | H29: BCA | I29: IDR | J29: =L29 -> 1200000000 | K29: 2025 | L29: =ROUNDDOWN(M29*N29,0) -> 1200000000 | M29: 1200000000 | N29: =VLOOKUP(I29,BUNGA!$C$97:$D$98,2,0) -> 1 | O29: SJ | P29: 2000000000 | Q29: 2000000000 | R29: 2000000000 | S29: 2000000000 | T29: 2000000000
A30: =A29+1 -> 23 | B30: =VLOOKUP(C30,$W:$X,2,0) -> 0305 | C30: OBLIGASI PEMERINTAH | D30: Indonesia | E30: 0013084496091000 | F30: BANK CENTRAL ASIA | G30: OBLIGASI FR74 | H30: BCA | I30: IDR | J30: =L30 -> 1600000000 | K30: 2025 | L30: =ROUNDDOWN(M30*N30,0) -> 1600000000 | M30: 1600000000 | N30: =VLOOKUP(I30,BUNGA!$C$97:$D$98,2,0) -> 1 | O30: SJ | P30: 2000000000 | Q30: 2000000000 | R30: 2000000000 | S30: 2000000000 | T30: 2000000000
A31: =A30+1 -> 24 | B31: =VLOOKUP(C31,$W:$X,2,0) -> 0305 | C31: OBLIGASI PEMERINTAH | D31: Indonesia | E31: 0013084496091000 | F31: BANK CENTRAL ASIA | G31: OBLIGASI FR79 | H31: BCA | I31: IDR | J31: =L31 -> 4500000000 | K31: 2025 | L31: =ROUNDDOWN(M31*N31,0) -> 4500000000 | M31: 4500000000 | N31: =VLOOKUP(I31,BUNGA!$C$97:$D$98,2,0) -> 1 | O31: SJ | P31: 4500000000 | Q31: 4500000000 | R31: 4500000000 | S31: 4500000000 | T31: 4500000000
A32: =A31+1 -> 25 | B32: =VLOOKUP(C32,$W:$X,2,0) -> 0305 | C32: OBLIGASI PEMERINTAH | D32: Indonesia | E32: 0013084496091000 | F32: BANK CENTRAL ASIA | G32: OBLIGASI FR065 | H32: BCA | I32: IDR | J32: =L32 -> 700000000 | K32: 2025 | L32: =ROUNDDOWN(M32*N32,0) -> 700000000 | M32: 700000000 | N32: =VLOOKUP(I32,BUNGA!$C$97:$D$98,2,0) -> 1 | O32: RC | P32: 2000000000 | Q32: 2000000000 | R32: 2000000000 | S32: 2000000000 | T32: 0
A33: =A32+1 -> 26 | B33: =VLOOKUP(C33,$W:$X,2,0) -> 0305 | C33: OBLIGASI PEMERINTAH | D33: Indonesia | E33: 0013084496091000 | F33: BANK CENTRAL ASIA | G33: OBLIGASI FR068 | H33: BCA | I33: IDR | J33: =L33 -> 1200000000 | K33: 2025 | L33: =ROUNDDOWN(M33*N33,0) -> 1200000000 | M33: 1200000000 | N33: =VLOOKUP(I33,BUNGA!$C$97:$D$98,2,0) -> 1 | O33: RC | P33: 2000000000 | Q33: 2000000000 | R33: 2000000000 | S33: 2000000000 | T33: 2000000000
A34: =A33+1 -> 27 | B34: =VLOOKUP(C34,$W:$X,2,0) -> 0305 | C34: OBLIGASI PEMERINTAH | D34: Indonesia | E34: 0013084496091000 | F34: BANK CENTRAL ASIA | G34: OBLIGASI FR072 | H34: BCA | I34: IDR | J34: =L34 -> 1000000000 | K34: 2025 | L34: =ROUNDDOWN(M34*N34,0) -> 1000000000 | M34: 1000000000 | N34: =VLOOKUP(I34,BUNGA!$C$97:$D$98,2,0) -> 1 | O34: RC | P34: 2000000000 | Q34: 2000000000 | R34: 2000000000 | S34: 2000000000 | T34: 2000000000
A35: =A34+1 -> 28 | B35: =VLOOKUP(C35,$W:$X,2,0) -> 0305 | C35: OBLIGASI PEMERINTAH | D35: Indonesia | E35: 0013084496091000 | F35: BANK CENTRAL ASIA | G35: OBLIGASI FR074 | H35: BCA | I35: IDR | J35: =L35 -> 1200000000 | K35: 2025 | L35: =ROUNDDOWN(M35*N35,0) -> 1200000000 | M35: 1200000000 | N35: =VLOOKUP(I35,BUNGA!$C$97:$D$98,2,0) -> 1 | O35: RC | P35: 2000000000 | Q35: 2000000000 | R35: 2000000000 | S35: 2000000000 | T35: 2000000000
A36: =A35+1 -> 29 | B36: =VLOOKUP(C36,$W:$X,2,0) -> 0305 | C36: OBLIGASI PEMERINTAH | D36: Indonesia | E36: 0013084496091000 | F36: BANK CENTRAL ASIA | G36: OBLIGASI FR079 | H36: BCA | I36: IDR | J36: =L36 -> 450000000 | K36: 2025 | L36: =ROUNDDOWN(M36*N36,0) -> 450000000 | M36: 450000000 | N36: =VLOOKUP(I36,BUNGA!$C$97:$D$98,2,0) -> 1 | O36: RC | P36: 700000000 | Q36: 700000000 | R36: 700000000 | S36: 700000000 | T36: 700000000
A37: =A36+1 -> 30 | B37: =VLOOKUP(C37,$W:$X,2,0) -> 0305 | C37: OBLIGASI PEMERINTAH | D37: Indonesia | E37: 0013084496091000 | F37: BANK CENTRAL ASIA | G37: OBLIGASI FR080 | H37: BCA | I37: IDR | J37: =L37 -> 400000000 | K37: 2025 | L37: =ROUNDDOWN(M37*N37,0) -> 400000000 | M37: 400000000 | N37: =VLOOKUP(I37,BUNGA!$C$97:$D$98,2,0) -> 1 | O37: RC | P37: 1000000000 | Q37: 1000000000 | R37: 1000000000 | S37: 1000000000 | T37: 1000000000
A38: =A37+1 -> 31 | B38: =VLOOKUP(C38,$W:$X,2,0) -> 0305 | C38: OBLIGASI PEMERINTAH | D38: Indonesia | E38: 0013084496091000 | F38: BANK CENTRAL ASIA | G38: OBLIGASI FR082 | H38: BCA | I38: IDR | J38: =L38 -> 2000000000 | K38: 2025 | L38: =ROUNDDOWN(M38*N38,0) -> 2000000000 | M38: 2000000000 | N38: =VLOOKUP(I38,BUNGA!$C$97:$D$98,2,0) -> 1 | O38: RC | P38: 3800000000 | Q38: 3800000000 | R38: 3800000000 | S38: 3800000000 | T38: 3800000000
A39: =A38+1 -> 32 | B39: =VLOOKUP(C39,$W:$X,2,0) -> 0305 | C39: OBLIGASI PEMERINTAH | D39: Indonesia | E39: 0013084496091000 | F39: BANK CENTRAL ASIA | G39: OBLIGASI FR091 | H39: BCA | I39: IDR | J39: =L39 -> 1000000000 | K39: 2025 | L39: =ROUNDDOWN(M39*N39,0) -> 1000000000 | M39: 1000000000 | N39: =VLOOKUP(I39,BUNGA!$C$97:$D$98,2,0) -> 1 | O39: RC | P39: 2000000000 | Q39: 2000000000 | R39: 2000000000 | S39: 2000000000 | T39: 0
A40: =A39+1 -> 33 | B40: =VLOOKUP(C40,$W:$X,2,0) -> 0305 | C40: OBLIGASI PEMERINTAH | D40: Indonesia | E40: 0013084496091000 | F40: BANK CENTRAL ASIA | G40: OBLIGASI INDOIS 30 USD | H40: BCA | I40: USD | J40: =L40 -> 694383253 | K40: 2025 | L40: =ROUNDDOWN(M40*N40,0) -> 694383253 | M40: 41389 | N40: =VLOOKUP(I40,BUNGA!$C$97:$D$98,2,0) -> 16777 | O40: RC | P40: 667025085 | Q40: 3100000000 | R40: 3100000000 | S40: 2858800000 | T40: 0
... A133: =A132+1 -> 126 | B133: =VLOOKUP(C133,$W:$X,2,0) -> 0307 | C133: REKSADANA | D133: Indonesia | E133: 0013084439091000 | F133: BANK UOB INDONESIA | G133: REKSADANA SCHRODER DANA MANTAP PLUS LL | H133: UOB | I133: IDR | J133: =L133 -> 2017035138 | K133: 2025 | L133: =ROUNDDOWN(M133*N133,0) -> 2017035138 | M133: 2017035138 | N133: =VLOOKUP(I133,BUNGA!$C$97:$D$98,2,0) -> 1 | O133: RC | P133: 0 | Q133: 0 | R133: 0 | S133: 0 | T133: 0
...

Sheet PIUTANG
C1: 2. PIUTANG
C2: Uang Tunai/Tabungan/Giro/Deposito
C4: 3173042409640005 | D4: SINDJAJA JONANY
I5: =SUM(I8:I55) -> 0 | K5: =SUM(K8:K55) -> 0 | L5: =SUM(L8:L55) -> 0 | M5: =SUM(M8:M55) -> 0 | N5: =SUM(N8:N55) -> 0 | O5: =SUM(O8:O55) -> 0
A6: NO | B6: KODE | C6: DESKRIPSI | D6: LOKASI PENERIMA PINJAMAN | E6: PENERIMA PINJAMAN | G6: NILAI PIUTANG | H6: TAHUN DIMULAI | I6: NILAI PIUTANG SAAT INI (2025) | J6: (HARTA PPS/ HARTA INVESTASI PPS) | K6: NILAI TAHUN SEBELUMNYA
E7: NIK / NPWP | F7: NAMA | K7: 2024 | L7: 2023 | M7: 2022 | N7: 2021 | O7: 2020 | Q7: - | R7: - | S7: -
A8: 1 | B8: =VLOOKUP(C8,$R:$S,2,0) -> - | C8: - | Q8: 0201 | R8: PIUTANG USAHA | S8: 0201
A9: =A8+1 -> 2 | Q9: 0202 | R9: PIUTANG AFILIASI | S9: 0202
A10: =A9+1 -> 3 | Q10: 0209 | R10: PIUTANG LAINNYA | S10: 0209
A11: =A10+1 -> 4
A12: =A11+1 -> 5
A13: =A12+1 -> 6
A14: =A13+1 -> 7
A15: =A14+1 -> 8
A16: =A15+1 -> 9
A17: =A16+1 -> 10
A18: =A17+1 -> 11
A19: =A18+1 -> 12
A20: =A19+1 -> 13
A21: =A20+1 -> 14
A22: =A21+1 -> 15
... A55: =A54+1 -> 48

Sheet HARTA BERGERAK
C1: 4. HARTA BERGERAK
C2: Motor/Mobil
C4: 3173042409640005 | D4: SINDJAJA JONANY | K4: CEK TYPE DI STNK (DIBAWAH TULISAN MERK)
J5: =SUM(J8:J55) -> 1858000000 | K5: =SUM(K8:K55) -> 1251300000 | M5: =SUM(M8:M55) -> 2287500000 | N5: =SUM(N8:N55) -> 1852500000 | O5: =SUM(O8:O55) -> 1852500000 | P5: =SUM(P8:P55) -> 2272500000 | Q5: =SUM(Q8:Q55) -> 1264500000
A6: NO | B6: KODE | C6: DESKRIPSI | E6: NOMOR POLISI/REGISTRASI | F6: KEPEMILIKAN | I6: TAHUN PEROLEHAN | J6: HARGA PEROLEHAN | K6: NILAI SAAT INI (2025) | L6: (Harta PPS/ Harta Investasi PPS) | M6: NILAI TAHUN SEBELUMNYA
C7: TIPE | D7: MEREK/MODEL | F7: MILIK SENDIRI/ ORANG LAIN | G7: NIK / NPWP | H7: NAMA | M7: 2024 | N7: 2023 | O7: 2022 | P7: 2021 | Q7: 2020 | S7: - | T7: - | U7: -
A8: 1 | B8: =VLOOKUP(C8,T:U,2,0) -> 0403 | C8: MOBIL PENUMPANG | D8: LEXUS RX300 | E8: B 1778 JYO | F8: OTHER | G8: 3173044110760006 | H8: ROSALINA CHANDRA | I8: 2021 | J8: 1407000000 | K8: 1008000000 | L8: - | M8: 1407000000 | N8: 1407000000 | O8: 1407000000 | P8: 1407000000 | Q8: 0 | S8: 0401 | T8: SEPEDA | U8: 0401
A9: 2 | B9: =VLOOKUP(C9,T:U,2,0) -> 0403 | C9: MOBIL PENUMPANG | D9: EV NETA X | E9: B 1309 UNS | F9: TAXPAYER | G9: 3173042409640005 | H9: SINDJAJA JONANY | I9: 2024 | J9: 435000000 | K9: 235000000 | L9: - | M9: 435000000 | N9: 0 | O9: 0 | P9: 0 | Q9: 0 | S9: 0402 | T9: SEPEDA MOTOR | U9: 0402
A10: 3 | B10: =VLOOKUP(C10,T:U,2,0) -> 0402 | C10: SEPEDA MOTOR | D10: YAMAHA VEGA ZR | E10: B 6697 BVO | F10: TAXPAYER | G10: 3173042409640005 | H10: SINDJAJA JONANY | I10: 2025 | J10: 8000000 | K10: 3600000 | L10: - | M10: 0 | N10: 0 | O10: 0 | P10: 0 | Q10: 0 | S10: 0403 | T10: MOBIL PENUMPANG | U10: 0403
A11: 4 | B11: =VLOOKUP(C11,T:U,2,0) -> 0402 | C11: SEPEDA MOTOR | D11: YAMAHA VEGA ZR | E11: B 3674 SBT | F11: TAXPAYER | G11: 3173042409640005 | H11: SINDJAJA JONANY | I11: 2025 | J11: 8000000 | K11: 4700000 | L11: - | M11: 0 | N11: 0 | O11: 0 | P11: 0 | Q11: 0 | S11: 0404 | T11: BUS | U11: 0404
S12: 0405 | T12: KENDARAAN ANGKUTAN JALAN | U12: 0405
C13: SEPEDA MOTOR | D13: MOTOR HONDA NF 100 | E13: B 4525 MK | I13: 2002 | J13: CLOSE | K13: CLOSE | L13: - | M13: 10500000 | N13: 10500000 | O13: 10500000 | P13: 10500000 | Q13: 10500000 | S13: 0406 | T13: KENDARAAN TUJUAN KHUSUS | U13: 0406
C14: MOBIL PENUMPANG | D14: TOYOTA FORTUNER 2.5G AT | E14: B 2178 MR | I14: 2015 | J14: CLOSE | K14: DILAPOR JUAL 2025. HARUSNYA 2024 | L14: - | M14: 435000000 | N14: 435000000 | O14: 435000000 | P14: 435000000 | Q14: 435000000 | S14: 0407 | T14: KERETA | U14: 0407
C15: MOBIL PENUMPANG | D15: VW GOLF Tsi | E15: NO.POL : B 668 ROS | I15: CLOSE | J15: CLOSE | K15: CLOSE | L15: - | M15: 0 | N15: 0 | O15: 0 | P15: 0 | Q15: 399000000 | S15: 0408 | T15: PESAWAT TERBANG | U15: 0408
C16: MOBIL PENUMPANG | D16: VW TIGUAN 1.4 AT | E16: B 1207 UJL | I16: CLOSE | J16: CLOSE | K16: CLOSE | L16: - | M16: 0 | N16: 0 | O16: 0 | P16: 420000000 | Q16: 420000000 | S16: 0409 | T16: KAPAL | U16: 0409
S17: 0410 | T17: MESIN | U17: 0410
S18: 0411 | T18: GEROBAK | U18: 0411
S19: 0412 | T19: KAPAL PESIAR | U19: 0412
S20: 0499 | T20: HARTA BERGERAK LAINNYA | U20: 0499
S22: OWNERSHIP MOVEABLE ASSET
S23: Code | T23: Code Description
S24: OTHER | T24: Atas nama pihak lain
S25: TAXPAYER | T25: Atas nama sendiri

Sheet HARTA TIDAK BERGERAK
C1: 5. HARTA TIDAK BERGERAK
C2: Tanah Kosong/Tanah Bangunan untuk Tempat Tinggal/Apartemen/Vessel/Tanah atau Lahan untuk Usaha/Tanah Bangunan untuk Usaha atau yang disewakan
C4: 3173042409640005 | D4: SINDJAJA JONANY | F4: CEK PBB 2025 | L4: CEK NJOP PBB 2025
K5: =SUM(K8:K55) -> 21454481063 | L5: =SUM(L8:L55) -> 57938723564 | N5: =SUM(N8:N55) -> 21454481063 | O5: =SUM(O8:O55) -> 19271771063 | P5: =SUM(P8:P55) -> 15371771063 | Q5: =SUM(Q8:Q55) -> 15251771063 | R5: =SUM(R8:R55) -> 14207771063
A6: NO | B6: KODE | C6: DESKRIPSI | D6: LOKASI HARTA | E6: DETAIL | F6: UKURAN PROPERTI | H6: SUMBER KEPEMILIKAN | I6: NOMOR SERTIFIKAT | J6: TAHUN PEROLEHAN | K6: HARGA PEROLEHAN | L6: NILAI SAAT INI (2025) | M6: (Harta PPS/ Harta Investasi PPS) | N6: NILAI TAHUN SEBELUMNYA
F7: TANAH | G7: BANGUNAN | N7: 2024 | O7: 2023 | P7: 2022 | Q7: 2021 | R7: 2020 | T7: - | U7: - | V7: -
A8: 1 | B8: =VLOOKUP(C8,$U:$V,2,0) -> 0502 | C8: TANAH DAN/ATAU BANGUNAN UNTUK TEMPAT TINGGAL | D8: Indonesia | E8: RUMAH, JL. KEADILAN V NO. 33 A, RT 012 RW 05, GLODOK, TAMAN SARI, JAKARTA BARAT | F8: 84 M2 | G8: 200 M2 | H8: Own Income | I8: 317405000500900900 | J8: 1992 | K8: 60000000 | L8: 1318220000 | M8: - | N8: 60000000 | O8: 60000000 | P8: 60000000 | Q8: 60000000 | R8: 60000000 | T8: 0501 | U8: TANAH KOSONG | V8: 0501 | W8: NOP: 31.71.070.001.013-0028.0
A9: =A8+1 -> 2 | B9: =VLOOKUP(C9,$U:$V,2,0) -> 0502 | C9: TANAH DAN/ATAU BANGUNAN UNTUK TEMPAT TINGGAL | D9: Indonesia | E9: RUMAH,JL.WALET INDAH I NO. 21, KAV.ST/NI-2, RT 14 RW 06, KAPUK MUARA, PENJARINGAN, JAKARTA UTARA | F9: 420 M2 | G9: 381 M2 | H9: Own Income | I9: 317501000204600030 | J9: 2001 | K9: 905310000 | L9: 10227585000 | M9: - | N9: 905310000 | O9: 905310000 | P9: 905310000 | Q9: 905310000 | R9: 905310000 | T9: 0502 | U9: TANAH DAN/ATAU BANGUNAN UNTUK TEMPAT TINGGAL | V9: 0502 | W9: NOP: 31.71.070.001.017-0141.0
A10: =A9+1 -> 3 | B10: =VLOOKUP(C10,$U:$V,2,0) -> 0501 | C10: TANAH KOSONG | D10: Indonesia | E10: KAVLING, LAKSANA BISNIS PARK UNIT BB02, LAKSANA, PAKU HAJI, KAB. TANGERANG, BANTEN | F10: 0 M2 | G10: 930 M2 | H10: Own Income | I10: 361915101300403160 | J10: 2016 | K10: 581250000 | L10: 959760000 | M10: - | N10: 581250000 | O10: 581250000 | P10: 581250000 | Q10: 581250000 | R10: 581250000 | T10: 0503 | U10: APARTEMEN | V10: 0503
A11: =A10+1 -> 4 | B11: =VLOOKUP(C11,$U:$V,2,0) -> 0501 | C11: TANAH KOSONG | D11: Indonesia | E11: KAVLING, LAKSANA BISNIS PARK UNIT BB03, LAKSANA, PAKU HAJI, KAB. TANGERANG, BANTEN | F11: 0 M2 | G11: 930 M2 | H11: Own Income | I11: 361915101300403170 | J11: 2016 | K11: 581250000 | L11: 959760000 | M11: - | N11: 581250000 | O11: 581250000 | P11: 581250000 | Q11: 581250000 | R11: 581250000 | T11: 0504 | U11: VESSEL | V11: 0504
A12: =A11+1 -> 5 | B12: =VLOOKUP(C12,$U:$V,2,0) -> 0501 | C12: TANAH KOSONG | D12: Indonesia | E12: TANAH, DESA KEDAUNG BARAT, SEPATAN TIMUR, KAB. TANGERANG, BANTEN | F12: 192 M2 | G12: 0 M2 | H12: Own Income | I12: AJB - MARTIA SH NO. 270 | J12: 2016 | K12: 30720000 | L12: 30720000 | M12: - | N12: 30720000 | O12: 30720000 | P12: 30720000 | Q12: 30720000 | R12: 30720000 | T12: 0505 | U12: TANAH ATAU LAHAN UNTUK USAHA (LAHAN PERTANIAN, PERKEBUNAN, DSB) | V12: 0505
A13: =A12+1 -> 6 | B13: =VLOOKUP(C13,$U:$V,2,0) -> 0502 | C13: TANAH DAN/ATAU BANGUNAN UNTUK TEMPAT TINGGAL | D13: Indonesia | E13: RUMAH, JL.WALET PERMAI 3 NO.7 ST/K7-08, KAPUK MUARA, PENJARINGAN, JAKARTA UTARA | F13: 175 M2 | G13: 198 M2 | H13: Own Income | I13: 317501000204501510 | J13: 2016 | K13: 2850000000 | L13: 4121625000 | M13: - | N13: 2850000000 | O13: 2850000000 | P13: 2850000000 | Q13: 2850000000 | R13: 2850000000 | T13: 0506 | U13: TANAH DAN/ATAU BANGUNAN UNTUK USAHA (TOKO, PABRIK, DSB) | V13: 0506
A14: =A13+1 -> 7 | B14: =VLOOKUP(C14,$U:$V,2,0) -> 0502 | C14: TANAH DAN/ATAU BANGUNAN UNTUK TEMPAT TINGGAL | D14: Indonesia | E14: RUMAH, PIK 2 TYPE GLADIOL, JL. TAMPA 2, SALEMBARAN JATI, KOSAMBI, KAB. TANGERANG, BANTEN | F14: 100 M2 | G14: 142 M2 | H14: Own Income | I14: 361916100200315650 | J14: 2021 | K14: 1164000000 | L14: 1164000000 | M14: 427100000 | N14: 1164000000 | O14: 1164000000 | P14: 1164000000 | Q14: 1044000000 | R14: 0 | T14: 0507 | U14: TANAH DAN/ATAU BANGUNAN YANG DISEWAKAN | V14: 0507
A15: =A14+1 -> 8 | B15: =VLOOKUP(C15,$U:$V,2,0) -> 0502 | C15: TANAH DAN/ATAU BANGUNAN UNTUK TEMPAT TINGGAL | D15: Indonesia | E15: RUMAH, JL. WALET BLOK E6. NO. 6 (BLOK R2 KAV. NO.9), RT 15 RW 06, KAPUK MUARA, PENJARINGAN, JAKARTA UTARA | F15: 175 M2 | G15: 131 M2 | H15: Own Income | I15: 317501000204700550 | J15: 2023 | K15: 3900000000 | L15: 3974225000 | M15: - | N15: 3900000000 | O15: 3900000000 | P15: 0 | Q15: 0 | R15: 0 | T15: 0509 | U15: HARTA TIDAK BERGERAK LAINNYA | V15: 0509
A16: =A15+1 -> 9 | B16: =VLOOKUP(C16,$U:$V,2,0) -> 0502 | C16: TANAH DAN/ATAU BANGUNAN UNTUK TEMPAT TINGGAL | D16: Indonesia | E16: RUMAH, JL. DANAU SINGKARAK G1/50, BENDUNGAN HILIR (KEPEMILIKAN 1/2 BAGIAN), JAKARTA PUSAT | F16: 217 M2 | G16: 164 M2 | H16: Own Income | I16: 317301000201300590 | J16: 2024 | K16: 2350000000 | L16: =4606543000/2 -> 2303271500 | M16: - | N16: 2350000000 | O16: 0 | P16: 0 | Q16: 0 | R16: 0
A17: =A16+1 -> 10 | B17: =VLOOKUP(C17,$U:$V,2,0) -> 0506 | C17: TANAH DAN/ATAU BANGUNAN UNTUK USAHA (TOKO, PABRIK, DSB) | D17: Indonesia | E17: TOKO, JEMBATAN ITC MG II LTI III/ BLOK A/3, ANCOL, PADEMANGAN, JAKARTA UTARA | F17: 0 M2 | G17: 20 M2 | H17: Own Income | I17: 317501100302013190 | J17: 1999 | K17: 170000000 | L17: 511180000 | M17: - | N17: 170000000 | O17: 170000000 | P17: 170000000 | Q17: 170000000 | R17: 170000000
A18: =A17+1 -> 11 | B18: =VLOOKUP(C18,$U:$V,2,0) -> 0506 | C18: TANAH DAN/ATAU BANGUNAN UNTUK USAHA (TOKO, PABRIK, DSB) | D18: Indonesia | E18: RUKO, JL. MANGGA DUA RAYA BLOK F-5 NO.15, RT 03 RW 13, MANGGA DUA SELATAN, SAWAH BESAR, JAKARTA PUSAT | F18: 63 M2 | G18: 219 M2 | H18: Own Income | I18: 317306000500208350 | J18: 2000 | K18: 490500000 | L18: 3154842000 | M18: - | N18: 490500000 | O18: 490500000 | P18: 490500000 | Q18: 490500000 | R18: 490500000 | T18: Source of Income
A19: =A18+1 -> 12 | B19: =VLOOKUP(C19,$U:$V,2,0) -> 0506 | C19: TANAH DAN/ATAU BANGUNAN UNTUK USAHA (TOKO, PABRIK, DSB) | D19: Indonesia | E19: RUKO, JL. MANGGA DUA RAYA BLOK F-5 NO.16, RT 03 RW 13, MANGGA DUA SELATAN, SAWAH BESAR, JAKARTA PUSAT | F19: 76 M2 | G19: 304 M2 | H19: Own Income | I19: 317306000500200900 | J19: 2003 | K19: 600000000 | L19: 4119580000 | M19: - | N19: 600000000 | O19: 600000000 | P19: 600000000 | Q19: 600000000 | R19: 600000000 | T19: Code Name | U19: Code Description
A20: =A19+1 -> 13 | B20: =VLOOKUP(C20,$U:$V,2,0) -> 0506 | C20: TANAH DAN/ATAU BANGUNAN UNTUK USAHA (TOKO, PABRIK, DSB) | D20: Indonesia | E20: TOKO, JEMBATAN ITC LT.II BLOK A NO.69, ANCOL, PADEMANGAN, JAKARTA UTARA | F20: 0 M2 | G20: 17 M2 | H20: Own Income | I20: 317501100302009920 | J20: 2003 | K20: 230000000 | L20: 409265000 | M20: - | N20: 230000000 | O20: 230000000 | P20: 230000000 | Q20: 230000000 | R20: 230000000 | T20: Debt | U20: Utang
A21: =A20+1 -> 14 | B21: =VLOOKUP(C21,$U:$V,2,0) -> 0502 | C21: TANAH DAN/ATAU BANGUNAN UNTUK TEMPAT TINGGAL | D21: Indonesia | E21: RUMAH, JL. CAMAR INDAH I BLOK D-A NO.12, KAPUK MUARA, PENJARINGAN, JAKARTA UTARA | F21: 100 M2 | G21: 316 M2 | H21: Own Income | I21: 317501000204302860 | J21: 2008 | K21: 1450000000 | L21: 3211900000 | M21: - | N21: 1450000000 | O21: 1450000000 | P21: 1450000000 | Q21: 1450000000 | R21: 1450000000 | T21: Gift | U21: Hadiah
A22: =A21+1 -> 15 | B22: =VLOOKUP(C22,$U:$V,2,0) -> 0506 | C22: TANAH DAN/ATAU BANGUNAN UNTUK USAHA (TOKO, PABRIK, DSB) | D22: Indonesia | E22: KOMPLEK PERGUDANGAN SENTRA INDUSTRI TERPADU PIK, BLOK E2 NO. 55, KAMAL MUARA, PENJARINGAN, JAKARTA UTARA | F22: 162 M2 | G22: 252 M2 | H22: Own Income | I22: 317501000101401930 | J22: 2009 | K22: 472843636 | L22: 2437506000 | M22: - | N22: 472843636 | O22: 472843636 | P22: 472843636 | Q22: 472843636 | R22: 472843636 | T22: Grant | U22: Hibah
A23: =A22+1 -> 16 | B23: =VLOOKUP(C23,$U:$V,2,0) -> 0506 | C23: TANAH DAN/ATAU BANGUNAN UNTUK USAHA (TOKO, PABRIK, DSB) | D23: Indonesia | E23: KOMPLEK PERGUDANGAN SENTRA INDUSTRI TERPADU PIK, BLOK E2 NO. 56, KAMAL MUARA, PENJARINGAN, JAKARTA UTARA | F23: 162 M2 | G23: 252 M2 | H23: Own Income | I23: 317501000101401940 | J23: 2009 | K23: 472843636 | L23: 2437506000 | M23: - | N23: 472843636 | O23: 472843636 | P23: 472843636 | Q23: 472843636 | R23: 472843636 | T23: Inheritance | U23: Warisan
A24: =A23+1 -> 17 | B24: =VLOOKUP(C24,$U:$V,2,0) -> 0506 | C24: TANAH DAN/ATAU BANGUNAN UNTUK USAHA (TOKO, PABRIK, DSB) | D24: Indonesia | E24: KOMPLEK PERGUDANGAN SENTRA INDUSTRI TERPADU PIK, BLOK E2 NO. 57, KAMAL MUARA, PENJARINGAN, JAKARTA UTARA | F24: 162 M2 | G24: 252 M2 | H24: Own Income | I24: 317501000101401950 | J24: 2009 | K24: 527570909 | L24: 2437506000 | M24: - | N24: 527570909 | O24: 527570909 | P24: 527570909 | Q24: 527570909 | R24: 527570909 | T24: Other sources | U24: Sumber lainnya
A25: =A24+1 -> 18 | B25: =VLOOKUP(C25,$U:$V,2,0) -> 0506 | C25: TANAH DAN/ATAU BANGUNAN UNTUK USAHA (TOKO, PABRIK, DSB) | D25: Indonesia | E25: KOMPLEK PERGUDANGAN SENTRA INDUSTRI TERPADU PIK, BLOK E2 NO. 58, KAMAL MUARA, PENJARINGAN, JAKARTA UTARA | F25: 162 M2 | G25: 252 M2 | H25: Own Income | I25: 317501000101401960 | J25: 2009 | K25: 527570909 | L25: 2437506000 | M25: - | N25: 527570909 | O25: 527570909 | P25: 527570909 | Q25: 527570909 | R25: 527570909 | T25: Own Income | U25: Hasil Sendiri
A26: =A25+1 -> 19 | B26: =VLOOKUP(C26,$U:$V,2,0) -> 0506 | C26: TANAH DAN/ATAU BANGUNAN UNTUK USAHA (TOKO, PABRIK, DSB) | D26: Indonesia | E26: TOKO, MANGGA DUA SQUARE UG-B145B, ANCOL, PADEMANGAN, JAKARTA UTARA | F26: 0 M2 | G26: 13 M2 | H26: Own Income | I26: 317501100302322570 | J26: 2009 | K26: 337336364 | L26: 337336364 | M26: 243069000 | N26: 337336364 | O26: 337336364 | P26: 337336364 | Q26: 337336364 | R26: 337336364
A27: =A26+1 -> 20 | B27: =VLOOKUP(C27,$U:$V,2,0) -> 0506 | C27: TANAH DAN/ATAU BANGUNAN UNTUK USAHA (TOKO, PABRIK, DSB) | D27: Indonesia | E27: KOMPLEK PERGUDANGAN SENTRA INDUSTRI TERPADU PIK, BLOK E2 NO. 59, KAMAL MUARA, PENJARINGAN, JAKARTA UTARA | F27: 162 M2 | G27: 252 M2 | H27: Own Income | I27: 317501000101401970 | J27: 2011 | K27: 527570909 | L27: 2437506000 | M27: - | N27: 527570909 | O27: 527570909 | P27: 527570909 | Q27: 527570909 | R27: 527570909
A28: =A27+1 -> 21 | B28: =VLOOKUP(C28,$U:$V,2,0) -> 0506 | C28: TANAH DAN/ATAU BANGUNAN UNTUK USAHA (TOKO, PABRIK, DSB) | D28: Indonesia | E28: RUKO, KOMPLEK TAMAN SURYA III BLOK J1 NO.14, PEGADUNGAN, KALIDERES, JAKARTA BARAT | F28: 144 M2 | G28: 180 M2 | H28: Own Income | I28: 317402100302904980 | J28: 2012 | K28: 567360000 | L28: 2055312000 | M28: - | N28: 567360000 | O28: 567360000 | P28: 567360000 | Q28: 567360000 | R28: 567360000
A29: =A28+1 -> 22 | B29: =VLOOKUP(C29,$U:$V,2,0) -> 0506 | C29: TANAH DAN/ATAU BANGUNAN UNTUK USAHA (TOKO, PABRIK, DSB) | D29: Indonesia | E29: RUKO, KOMPLEK TAMAN SURYA III BLOK J1 NO.15, PEGADUNGAN, KALIDERES, JAKARTA BARAT | F29: 156 M2 | G29: 180 M2 | H29: Own Income | I29: 317402100302904990 | J29: 2012 | K29: 567360000 | L29: 1945260000 | M29: - | N29: 567360000 | O29: 567360000 | P29: 567360000 | Q29: 567360000 | R29: 567360000
A30: =A29+1 -> 23 | B30: =VLOOKUP(C30,$U:$V,2,0) -> 0506 | C30: TANAH DAN/ATAU BANGUNAN UNTUK USAHA (TOKO, PABRIK, DSB) | D30: Indonesia | E30: RUKO, JL. MANGGA DUA RAYA BLOK F-5 NO.14, RT 03 RW 13, MANGGA DUA SELATAN, SAWAH BESAR, JAKARTA PUSAT | F30: 63 M2 | G30: 219 M2 | H30: Own Income | I30: 317306000500208340 | J30: 2016 | K30: 490500000 | L30: 3154842000 | M30: - | N30: 490500000 | O30: 490500000 | P30: 490500000 | Q30: 490500000 | R30: 490500000
A31: =A30+1 -> 24 | B31: =VLOOKUP(C31,$U:$V,2,0) -> 0506 | C31: TANAH DAN/ATAU BANGUNAN UNTUK USAHA (TOKO, PABRIK, DSB) | D31: Indonesia | E31: TOKO, JEMBATAN ITC LT.II BLOK A NO.68, ANCOL, PADEMANGAN, JAKARTA UTARA | F31: 0 M2 | G31: 16 M2 | H31: Own Income | I31: 317501100302009910 | J31: 2016 | K31: 210000000 | L31: 402015000 | M31: - | N31: 210000000 | O31: 210000000 | P31: 210000000 | Q31: 210000000 | R31: 210000000
A32: =A31+1 -> 25 | B32: =VLOOKUP(C32,$U:$V,2,0) -> 0506 | C32: TANAH DAN/ATAU BANGUNAN UNTUK USAHA (TOKO, PABRIK, DSB) | D32: Indonesia | E32: KIOS, PASAR PAGI MANGGA DUA LANTAI SB BLOK C NO.54 JAK-UT | F32: 0 M2 | G32: - | H32: Own Income | I32: - | J32: 2016 | K32: 31082000 | L32: 31082000 | M32: - | N32: 31082000 | O32: 31082000 | P32: 31082000 | Q32: 31082000 | R32: 31082000
A33: =A32+1 -> 26 | B33: =VLOOKUP(C33,$U:$V,2,0) -> 0506 | C33: TANAH DAN/ATAU BANGUNAN UNTUK USAHA (TOKO, PABRIK, DSB) | D33: Indonesia | E33: KIOS, PASAR PAGI MANGGA DUA LANTAI SB BLOK C NO.55 JAK-UT | F33: 0 M2 | G33: - | H33: Own Income | I33: - | J33: 2016 | K33: 31082000 | L33: 31082000 | M33: - | N33: 31082000 | O33: 31082000 | P33: 31082000 | Q33: 31082000 | R33: 31082000
A34: =A33+1 -> 27 | B34: =VLOOKUP(C34,$U:$V,2,0) -> 0506 | C34: TANAH DAN/ATAU BANGUNAN UNTUK USAHA (TOKO, PABRIK, DSB) | D34: Indonesia | E34: KIOS, PASAR PAGI MANGGA DUA LANTAI SB BLOK C NO.56 JAK-UT | F34: 0 M2 | G34: - | H34: Own Income | I34: - | J34: 2016 | K34: 41400000 | L34: 41400000 | M34: - | N34: 41400000 | O34: 41400000 | P34: 41400000 | Q34: 41400000 | R34: 41400000
A35: =A34+1 -> 28 | B35: =VLOOKUP(C35,$U:$V,2,0) -> 0506 | C35: TANAH DAN/ATAU BANGUNAN UNTUK USAHA (TOKO, PABRIK, DSB) | D35: Indonesia | E35: KIOS, PASAR TANAH ABANG BLOK B LANTAI L01 LOS FKS NO.056, KAMPUNG BALI, TANAH ABANG, JAKARTA PUSAT | F35: 0 M2 | G35: 5 M2 | H35: Own Income | I35: 317301000702431000 | J35: 2016 | K35: 678804500 | L35: 678804500 | M35: 326500000 | N35: 678804500 | O35: 678804500 | P35: 678804500 | Q35: 678804500 | R35: 678804500
A36: =A35+1 -> 29 | B36: =VLOOKUP(C36,$U:$V,2,0) -> 0506 | C36: TANAH DAN/ATAU BANGUNAN UNTUK USAHA (TOKO, PABRIK, DSB) | D36: Indonesia | E36: KIOS, PASAR TANAH ABANG BLOK B LANTAI L01 LOS FKS NO.057, KAMPUNG BALI, TANAH ABANG, JAKARTA PUSAT | F36: 0 M2 | G36: 4 M2 | H36: Own Income | I36: 317301000702431010 | J36: 2016 | K36: 608126200 | L36: 608126200 | M36: 293500000 | N36: 608126200 | O36: 608126200 | P36: 608126200 | Q36: 608126200 | R36: 608126200
C38: TANAH KOSONG | D38: Indonesia | E38: TANAH, DESA KEDAUNG BARAT, SEPATAN TIMUR, KAB. TANGERANG, BANTEN | F38: - | G38: 0 M2 | H38: Own Income | I38: - | J38: 2016 | K38: CLOSE | L38: CLOSE | M38: - | N38: 0 | O38: 6520000 | P38: 6520000 | Q38: 6520000 | R38: 6520000
C39: TANAH KOSONG | D39: Indonesia | E39: TANAH, DESA KEDAUNG BARAT, SEPATAN TIMUR, KAB. TANGERANG, BANTEN | F39: - | G39: 0 M2 | H39: Own Income | I39: - | J39: 2016 | K39: CLOSE | L39: CLOSE | N39: 0 | O39: 24740000 | P39: 24740000 | Q39: 24740000 | R39: 24740000
C40: TANAH KOSONG | D40: Indonesia | E40: TANAH, DESA KEDAUNG BARAT, SEPATAN TIMUR, KAB. TANGERANG, BANTEN | F40: - | G40: 0 M2 | H40: Own Income | I40: - | J40: 2016 | K40: CLOSE | L40: CLOSE | N40: 0 | O40: 29400000 | P40: 29400000 | Q40: 29400000 | R40: 29400000
C41: TANAH KOSONG | D41: Indonesia | E41: TANAH, DESA KEDAUNG BARAT, SEPATAN TIMUR, KAB. TANGERANG, BANTEN | F41: - | G41: 0 M2 | H41: Own Income | I41: - | J41: 2016 | K41: CLOSE | L41: CLOSE | N41: 0 | O41: 27740000 | P41: 27740000 | Q41: 27740000 | R41: 27740000
C42: TANAH KOSONG | D42: Indonesia | E42: TANAH, DESA KEDAUNG BARAT, SEPATAN TIMUR, KAB. TANGERANG, BANTEN | F42: - | G42: 0 M2 | H42: Own Income | I42: - | J42: 2016 | K42: CLOSE | L42: CLOSE | N42: 0 | O42: 27850000 | P42: 27850000 | Q42: 27850000 | R42: 27850000
...

Sheet HIT 2024
B1: NO. | C1: KODE | D1: NAMA HARTA | E1: TAHUN PEROLEHAN | F1: HARGA PEROLEHAN | G1: KETERANGAN
B2: 1 | C2: 061 | D2: TANAH DAN RUMAH LAMANDAU | E2: 2009 | F2: 1320000000 | G2: JALAN LAMANDAU 1 NO. 19
B3: 2 | C3: 061 | D3: APARTEMEN SERPONG MIDTOWN | E3: 2016 | F3: 1538793523 | G3: PPJB
B4: 3 | C4: 061 | D4: TANAH DAN BANGUNAN DESA LEGOK | E4: 2016 | F4: 1987500000 | G4: JL. DESA LEGOK GAOK RT. 02 RW. 05
B5: 4 | C5: 061 | D5: TANAH KELURAHAN TANJUNG DUREN SELATAN, GROGOL | E5: 2016 | F5: 350370000 | G5: 1609/XIII/CATTELYA
B6: 5 | C6: 061 | D6: TANAH DAN BANGUNAN SENTRA BUMI NIAGA SURYA GRAND | E6: 2016 | F6: 1025000000 | G6: 006/LG/PPJB-SP/XI/16 | H6: =SUM(F2:F6) -> 6221663523
B7: 6 | C7: 062 | D7: APARTEMEN LUCKY TOWER RESIDENCE | E7: 2016 | F7: 2554200000 | G7: 00004/PP-APT/SMU/III/2014
B8: 7 | C8: 043 | D8: MOBIL SMART PASSION | E8: 2010 | F8: 220000000 | G8: NO. POL : B 1660 SOE
B9: 8 | C9: 043 | D9: MOBIL BMW X5 | E9: 2020 | F9: 980000000 | G9: NO.POL : B 2523 SXP - 70600392011
B10: 9 | C10: 043 | D10: MOBIL ALPHARD | E10: 2021 | F10: 1240500000 | G10: NO. POL : B 304 DEV - 70601882111 | H10: =SUM(H6+SUM(F7:F10)) -> 11216363523
B11: 10 | C11: 051 | D11: PERHIASAN | E11: 2019 | F11: 4763000000
B12: 11 | C12: 051 | D12: PERHIASAN | E12: 2019 | F12: 87000000
B13: 12 | C13: 053 | D13: PERABOTAN DAN SENI | E13: 2019 | F13: 1086000000
B14: 13 | C14: 053 | D14: KOLEKSI UANG KUNO | E14: 2019 | F14: 360000000 | H14: =SUM(H10+SUM(F11:F14)) -> 17512363523
B15: 14 | C15: 053 | D15: PERABOTAN DAN SENI | E15: 2019 | F15: 14000000
B16: 15 | C16: 011 | D16: VALUTA ASING USD | E16: 2019 | F16: 3564000000
B17: 16 | C17: 011 | D17: VALUTA ASING AUD | E17: 2024 | F17: 504094000
B18: 17 | C18: 032 | D18: SAHAM BATAVIA LAND | E18: 2016 | F18: 5700000000 | G18: AKTA NO. 14 | H18: =SUM(H14+SUM(F15:F18)) -> 27294457523
B19: 18 | C19: 031 | D19: SAHAM PT. FAC SEKURITAS INDONESIA | E19: 2020 | F19: 86958597
B20: 19 | C20: 012 | D20: TABUNGAN | E20: 2024 | F20: 1689737 | G20: PANIN USD - 1004008898
B21: 20 | C21: 012 | D21: TABUNGAN | E21: 2024 | F21: 48293672 | G21: WELLS FARGO, USA (USD) - 3908725520
B22: 21 | C22: 012 | D22: TABUNGAN | E22: 2024 | F22: 1.008188e+08 | G22: HSBC, AUS (AUD) - 012615621118 | H22: =SUM(H18+SUM(F19:F22)) -> 27532218329
B23: 22 | C23: 012 | D23: TABUNGAN | E23: 2024 | F23: 47297325 | G23: HSBC, AUS (AUD) - 012640249090
B24: 23 | C24: 012 | D24: TABUNGAN | E24: 2024 | F24: 527718970 | G24: HSBC, AUS (USD) - 012640249090
B25: 24 | C25: 014 | D25: DEPOSITO | E25: 2024 | F25: 912979464 | G25: HSBC, AUS (AUD) - 012615621053
B26: 25 | C26: 013 | D26: TABUNGAN GIRO | E26: 2024 | F26: 5526951 | G26: HSBC, HKG (HKD) - 622168102888 | H26: =SUM(H22+SUM(F23:F26)) -> 29025741039
B27: 26 | C27: 012 | D27: TABUNGAN | E27: 2024 | F27: 20820000 | G27: HSBC, HKG (HKD) - 622168102888
B28: 27 | C28: 012 | D28: TABUNGAN | E28: 2024 | F28: 26092256 | G28: HSBC, HKG (USD) - 622168102888
B29: 28 | C29: 012 | D29: TABUNGAN | E29: 2024 | F29: 103772808 | G29: OCBC, SGP (USD) - 508013802201
B30: 29 | C30: 012 | D30: TABUNGAN | E30: 2024 | F30: 102044280 | G30: OCBC, SGP (SGD) - 6524013254 | H30: =SUM(H26+SUM(F27:F30)) -> 29278470383
B31: 30 | C31: 012 | D31: TABUNGAN | E31: 2024 | F31: 17878500 | G31: OCBC, SGP (SGD) - 6521012150
B32: 31 | C32: 012 | D32: TABUNGAN | E32: 2024 | F32: 286056000 | G32: OCBC, SGP (SGD) - 584269120001
B33: 32 | C33: 012 | D33: TABUNGAN | E33: 2024 | F33: 0 | G33: OCBC, SGP (SGD) - 584269138001
B34: 33 | C34: 014 | D34: DEPOSITO | E34: 2024 | F34: 441058879 | G34: OCBC, SGP (USD) - 508655545401 | H34: =SUM(H30+SUM(F31:F34)) -> 30023463762
B35: 34 | C35: 014 | D35: DEPOSITO | E35: 2024 | F35: 264098555 | G35: OCBC, SGP (USD) - 508655545401
B36: 35 | C36: 014 | D36: DEPOSITO | E36: 2024 | F36: 876232850 | G36: OCBC, SGP (USD) - 508655545401
B37: 36 | C37: 014 | D37: DEPOSITO | E37: 2024 | F37: 876232850 | G37: OCBC, SGP (USD) - 508655545401
B38: 37 | C38: 012 | D38: TABUNGAN | E38: 2024 | F38: 180943 | G38: PANIN - 1002000998 | H38: =SUM(H34+SUM(F35:F38)) -> 32040208960
B39: 38 | C39: 012 | D39: TABUNGAN | E39: 2024 | F39: 5272572 | G39: PANIN - 1002890077
B40: 39 | C40: 012 | D40: TABUNGAN | E40: 2024 | F40: 803897 | G40: PANIN USD - 1004307679
...

Sheet HARTA LAINNYA
C1: 6. HARTA LAINNYA
C2: Emas Batangan/Emas Perhiasan/Permata/Barang Barang Seni dan Antik/Peralatan Elektronik/Perabot Rumah Tangga/Harta Tidak Berwujud Lainnya
C4: 3173042409640005 | D4: SINDJAJA JONANY
